/usr/local/lib/python2.7/dist-packages/flask_sqlalchemy/__init__.py:800: UserWarning: SQLALCHEMY_TRACK_MODIFICATIONS adds significant overhead and will be disabled by default in the future.  Set it to True to suppress this warning.
  warnings.warn('SQLALCHEMY_TRACK_MODIFICATIONS adds significant overhead and will be disabled by default in the future.  Set it to True to suppress this warning.')
 * Running on http://0.0.0.0:9000/ (Press CTRL+C to quit)
 * Restarting with stat
/usr/local/lib/python2.7/dist-packages/flask_sqlalchemy/__init__.py:800: UserWarning: SQLALCHEMY_TRACK_MODIFICATIONS adds significant overhead and will be disabled by default in the future.  Set it to True to suppress this warning.
  warnings.warn('SQLALCHEMY_TRACK_MODIFICATIONS adds significant overhead and will be disabled by default in the future.  Set it to True to suppress this warning.')
 * Debugger is active!
 * Debugger pin code: 166-222-627
46.225.179.126 - - [05/Oct/2016 07:23:58] "GET / HTTP/1.1" 200 -
46.225.179.126 - - [05/Oct/2016 07:24:02] "GET /author HTTP/1.1" 200 -
93.174.93.136 - - [05/Oct/2016 14:55:16] "GET http://www.baidu.com/cache/global/img/gs.gif HTTP/1.1" 404 -
194.225.232.96 - - [05/Oct/2016 23:00:37] "POST /signup/using_email HTTP/1.1" 200 -
94.24.93.131 - - [05/Oct/2016 23:42:19] "POST /signup/using_phonenumber HTTP/1.1" 500 -
Traceback (most recent call last):
  File "/usr/local/lib/python2.7/dist-packages/flask/app.py", line 2000, in __call__
    return self.wsgi_app(environ, start_response)
  File "/usr/local/lib/python2.7/dist-packages/flask/app.py", line 1991, in wsgi_app
    response = self.make_response(self.handle_exception(e))
  File "/usr/local/lib/python2.7/dist-packages/flask/app.py", line 1567, in handle_exception
    reraise(exc_type, exc_value, tb)
  File "/usr/local/lib/python2.7/dist-packages/flask/app.py", line 1988, in wsgi_app
    response = self.full_dispatch_request()
  File "/usr/local/lib/python2.7/dist-packages/flask/app.py", line 1641, in full_dispatch_request
    rv = self.handle_user_exception(e)
  File "/usr/local/lib/python2.7/dist-packages/flask/app.py", line 1544, in handle_user_exception
    reraise(exc_type, exc_value, tb)
  File "/usr/local/lib/python2.7/dist-packages/flask/app.py", line 1639, in full_dispatch_request
    rv = self.dispatch_request()
  File "/usr/local/lib/python2.7/dist-packages/flask/app.py", line 1625, in dispatch_request
    return self.view_functions[rule.endpoint](**req.view_args)
  File "/root/move_it/app/main/views.py", line 186, in signup_using_phonenumber
    response = methods.send_signup_code(phonenumber=request.json['phonenumber'], code=code)
  File "/root/move_it/app/main/methods.py", line 20, in send_signup_code
    print response.text
UnicodeEncodeError: 'ascii' codec can't encode characters in position 0-4: ordinal not in range(128)
194.225.232.96 - - [05/Oct/2016 23:42:27] "GET /signup/using_phonenumber HTTP/1.1" 405 -
194.225.232.96 - - [05/Oct/2016 23:42:27] "GET /favicon.ico HTTP/1.1" 404 -
194.225.232.96 - - [05/Oct/2016 23:53:02] "POST /signup/using_phonenumber HTTP/1.1" 500 -
Traceback (most recent call last):
  File "/usr/local/lib/python2.7/dist-packages/flask/app.py", line 2000, in __call__
    return self.wsgi_app(environ, start_response)
  File "/usr/local/lib/python2.7/dist-packages/flask/app.py", line 1991, in wsgi_app
    response = self.make_response(self.handle_exception(e))
  File "/usr/local/lib/python2.7/dist-packages/flask/app.py", line 1567, in handle_exception
    reraise(exc_type, exc_value, tb)
  File "/usr/local/lib/python2.7/dist-packages/flask/app.py", line 1988, in wsgi_app
    response = self.full_dispatch_request()
  File "/usr/local/lib/python2.7/dist-packages/flask/app.py", line 1641, in full_dispatch_request
    rv = self.handle_user_exception(e)
  File "/usr/local/lib/python2.7/dist-packages/flask/app.py", line 1544, in handle_user_exception
    reraise(exc_type, exc_value, tb)
  File "/usr/local/lib/python2.7/dist-packages/flask/app.py", line 1639, in full_dispatch_request
    rv = self.dispatch_request()
  File "/usr/local/lib/python2.7/dist-packages/flask/app.py", line 1625, in dispatch_request
    return self.view_functions[rule.endpoint](**req.view_args)
  File "/root/move_it/app/main/views.py", line 186, in signup_using_phonenumber
    response = methods.send_signup_code(phonenumber=request.json['phonenumber'], code=code)
  File "/root/move_it/app/main/methods.py", line 20, in send_signup_code
    print response.text
UnicodeEncodeError: 'ascii' codec can't encode characters in position 0-4: ordinal not in range(128)
94.24.93.131 - - [06/Oct/2016 00:11:14] "POST /signup%2Fusing_email HTTP/1.1" 500 -
Traceback (most recent call last):
  File "/usr/local/lib/python2.7/dist-packages/flask/app.py", line 2000, in __call__
    return self.wsgi_app(environ, start_response)
  File "/usr/local/lib/python2.7/dist-packages/flask/app.py", line 1991, in wsgi_app
    response = self.make_response(self.handle_exception(e))
  File "/usr/local/lib/python2.7/dist-packages/flask/app.py", line 1567, in handle_exception
    reraise(exc_type, exc_value, tb)
  File "/usr/local/lib/python2.7/dist-packages/flask/app.py", line 1988, in wsgi_app
    response = self.full_dispatch_request()
  File "/usr/local/lib/python2.7/dist-packages/flask/app.py", line 1641, in full_dispatch_request
    rv = self.handle_user_exception(e)
  File "/usr/local/lib/python2.7/dist-packages/flask/app.py", line 1544, in handle_user_exception
    reraise(exc_type, exc_value, tb)
  File "/usr/local/lib/python2.7/dist-packages/flask/app.py", line 1639, in full_dispatch_request
    rv = self.dispatch_request()
  File "/usr/local/lib/python2.7/dist-packages/flask/app.py", line 1625, in dispatch_request
    return self.view_functions[rule.endpoint](**req.view_args)
  File "/root/move_it/app/main/views.py", line 253, in signup_using_email
    email=request.json['email'],
KeyError: 'email'
94.24.93.131 - - [06/Oct/2016 00:13:36] "POST /signup%2Fusing_phonenumber HTTP/1.1" 500 -
Traceback (most recent call last):
  File "/usr/local/lib/python2.7/dist-packages/flask/app.py", line 2000, in __call__
    return self.wsgi_app(environ, start_response)
  File "/usr/local/lib/python2.7/dist-packages/flask/app.py", line 1991, in wsgi_app
    response = self.make_response(self.handle_exception(e))
  File "/usr/local/lib/python2.7/dist-packages/flask/app.py", line 1567, in handle_exception
    reraise(exc_type, exc_value, tb)
  File "/usr/local/lib/python2.7/dist-packages/flask/app.py", line 1988, in wsgi_app
    response = self.full_dispatch_request()
  File "/usr/local/lib/python2.7/dist-packages/flask/app.py", line 1641, in full_dispatch_request
    rv = self.handle_user_exception(e)
  File "/usr/local/lib/python2.7/dist-packages/flask/app.py", line 1544, in handle_user_exception
    reraise(exc_type, exc_value, tb)
  File "/usr/local/lib/python2.7/dist-packages/flask/app.py", line 1639, in full_dispatch_request
    rv = self.dispatch_request()
  File "/usr/local/lib/python2.7/dist-packages/flask/app.py", line 1625, in dispatch_request
    return self.view_functions[rule.endpoint](**req.view_args)
  File "/root/move_it/app/main/views.py", line 186, in signup_using_phonenumber
    response = methods.send_signup_code(phonenumber=request.json['phonenumber'], code=code)
  File "/root/move_it/app/main/methods.py", line 20, in send_signup_code
    print response.text
UnicodeEncodeError: 'ascii' codec can't encode characters in position 0-4: ordinal not in range(128)
66.249.93.5 - - [06/Oct/2016 00:20:12] "GET /admin HTTP/1.1" 301 -
66.249.93.7 - - [06/Oct/2016 00:20:12] "GET /admin/ HTTP/1.1" 200 -
66.249.93.9 - - [06/Oct/2016 00:20:13] "GET /admin/static/bootstrap/bootstrap3/css/bootstrap.min.css?v=3.3.5 HTTP/1.1" 200 -
66.249.93.7 - - [06/Oct/2016 00:20:13] "GET /admin/static/bootstrap/bootstrap3/css/bootstrap-theme.min.css?v=3.3.5 HTTP/1.1" 200 -
66.249.93.5 - - [06/Oct/2016 00:20:13] "GET /admin/static/admin/css/bootstrap3/admin.css?v=1.1.1 HTTP/1.1" 200 -
66.249.93.9 - - [06/Oct/2016 00:20:13] "GET /admin/static/vendor/jquery.min.js?v=2.1.4 HTTP/1.1" 200 -
66.249.93.5 - - [06/Oct/2016 00:20:13] "GET /admin/static/vendor/moment.min.js?v=2.9.0 HTTP/1.1" 200 -
66.249.93.5 - - [06/Oct/2016 00:20:13] "GET /admin/static/bootstrap/bootstrap3/js/bootstrap.min.js?v=3.3.5 HTTP/1.1" 200 -
66.249.93.7 - - [06/Oct/2016 00:20:13] "GET /admin/static/vendor/select2/select2.min.js?v=3.5.2 HTTP/1.1" 200 -
66.249.93.7 - - [06/Oct/2016 00:20:20] "GET /admin/user/ HTTP/1.1" 200 -
66.249.93.9 - - [06/Oct/2016 00:20:20] "GET /admin/static/vendor/select2/select2-bootstrap3.css?v=1.4.6 HTTP/1.1" 200 -
66.249.93.9 - - [06/Oct/2016 00:20:20] "GET /admin/static/admin/js/filters.js?v=1.0.0 HTTP/1.1" 200 -
66.249.93.9 - - [06/Oct/2016 00:20:20] "GET /admin/static/vendor/select2/select2.css?v=3.5.2 HTTP/1.1" 200 -
66.249.93.7 - - [06/Oct/2016 00:20:20] "GET /admin/static/vendor/bootstrap-daterangepicker/daterangepicker.js?v=1.3.22 HTTP/1.1" 200 -
66.249.93.5 - - [06/Oct/2016 00:20:20] "GET /admin/static/vendor/bootstrap-daterangepicker/daterangepicker-bs3.css?v=1.3.22 HTTP/1.1" 200 -
66.249.93.5 - - [06/Oct/2016 00:20:20] "GET /admin/static/admin/js/form.js?v=1.0.1 HTTP/1.1" 200 -
66.249.93.7 - - [06/Oct/2016 00:20:20] "GET /admin/static/admin/js/actions.js?v=1.0.0 HTTP/1.1" 200 -
66.249.93.5 - - [06/Oct/2016 00:20:20] "GET /admin/static/bootstrap/bootstrap3/fonts/glyphicons-halflings-regular.woff2 HTTP/1.1" 200 -
194.225.232.96 - - [06/Oct/2016 00:20:20] "GET /admin/static/bootstrap/bootstrap3/fonts/glyphicons-halflings-regular.woff2 HTTP/1.1" 200 -
94.24.93.131 - - [06/Oct/2016 00:21:14] "POST /signup%2Fusing_phonenumber HTTP/1.1" 500 -
Traceback (most recent call last):
  File "/usr/local/lib/python2.7/dist-packages/flask/app.py", line 2000, in __call__
    return self.wsgi_app(environ, start_response)
  File "/usr/local/lib/python2.7/dist-packages/flask/app.py", line 1991, in wsgi_app
    response = self.make_response(self.handle_exception(e))
  File "/usr/local/lib/python2.7/dist-packages/flask/app.py", line 1567, in handle_exception
    reraise(exc_type, exc_value, tb)
  File "/usr/local/lib/python2.7/dist-packages/flask/app.py", line 1988, in wsgi_app
    response = self.full_dispatch_request()
  File "/usr/local/lib/python2.7/dist-packages/flask/app.py", line 1641, in full_dispatch_request
    rv = self.handle_user_exception(e)
  File "/usr/local/lib/python2.7/dist-packages/flask/app.py", line 1544, in handle_user_exception
    reraise(exc_type, exc_value, tb)
  File "/usr/local/lib/python2.7/dist-packages/flask/app.py", line 1639, in full_dispatch_request
    rv = self.dispatch_request()
  File "/usr/local/lib/python2.7/dist-packages/flask/app.py", line 1625, in dispatch_request
    return self.view_functions[rule.endpoint](**req.view_args)
  File "/root/move_it/app/main/views.py", line 186, in signup_using_phonenumber
    response = methods.send_signup_code(phonenumber=request.json['phonenumber'], code=code)
  File "/root/move_it/app/main/methods.py", line 20, in send_signup_code
    print response.text
UnicodeEncodeError: 'ascii' codec can't encode characters in position 0-4: ordinal not in range(128)
94.24.93.131 - - [06/Oct/2016 00:31:49] "POST /signup%2Fusing_phonenumber HTTP/1.1" 500 -
Traceback (most recent call last):
  File "/usr/local/lib/python2.7/dist-packages/flask/app.py", line 2000, in __call__
    return self.wsgi_app(environ, start_response)
  File "/usr/local/lib/python2.7/dist-packages/flask/app.py", line 1991, in wsgi_app
    response = self.make_response(self.handle_exception(e))
  File "/usr/local/lib/python2.7/dist-packages/flask/app.py", line 1567, in handle_exception
    reraise(exc_type, exc_value, tb)
  File "/usr/local/lib/python2.7/dist-packages/flask/app.py", line 1988, in wsgi_app
    response = self.full_dispatch_request()
  File "/usr/local/lib/python2.7/dist-packages/flask/app.py", line 1641, in full_dispatch_request
    rv = self.handle_user_exception(e)
  File "/usr/local/lib/python2.7/dist-packages/flask/app.py", line 1544, in handle_user_exception
    reraise(exc_type, exc_value, tb)
  File "/usr/local/lib/python2.7/dist-packages/flask/app.py", line 1639, in full_dispatch_request
    rv = self.dispatch_request()
  File "/usr/local/lib/python2.7/dist-packages/flask/app.py", line 1625, in dispatch_request
    return self.view_functions[rule.endpoint](**req.view_args)
  File "/root/move_it/app/main/views.py", line 186, in signup_using_phonenumber
    response = methods.send_signup_code(phonenumber=request.json['phonenumber'], code=code)
  File "/root/move_it/app/main/methods.py", line 20, in send_signup_code
    print response.text
UnicodeEncodeError: 'ascii' codec can't encode characters in position 0-4: ordinal not in range(128)
94.24.93.131 - - [06/Oct/2016 00:35:34] "POST /signup%2Fusing_phonenumber HTTP/1.1" 500 -
Traceback (most recent call last):
  File "/usr/local/lib/python2.7/dist-packages/flask/app.py", line 2000, in __call__
    return self.wsgi_app(environ, start_response)
  File "/usr/local/lib/python2.7/dist-packages/flask/app.py", line 1991, in wsgi_app
    response = self.make_response(self.handle_exception(e))
  File "/usr/local/lib/python2.7/dist-packages/flask/app.py", line 1567, in handle_exception
    reraise(exc_type, exc_value, tb)
  File "/usr/local/lib/python2.7/dist-packages/flask/app.py", line 1988, in wsgi_app
    response = self.full_dispatch_request()
  File "/usr/local/lib/python2.7/dist-packages/flask/app.py", line 1641, in full_dispatch_request
    rv = self.handle_user_exception(e)
  File "/usr/local/lib/python2.7/dist-packages/flask/app.py", line 1544, in handle_user_exception
    reraise(exc_type, exc_value, tb)
  File "/usr/local/lib/python2.7/dist-packages/flask/app.py", line 1639, in full_dispatch_request
    rv = self.dispatch_request()
  File "/usr/local/lib/python2.7/dist-packages/flask/app.py", line 1625, in dispatch_request
    return self.view_functions[rule.endpoint](**req.view_args)
  File "/root/move_it/app/main/views.py", line 186, in signup_using_phonenumber
    response = methods.send_signup_code(phonenumber=request.json['phonenumber'], code=code)
  File "/root/move_it/app/main/methods.py", line 20, in send_signup_code
    print response.text
UnicodeEncodeError: 'ascii' codec can't encode characters in position 0-4: ordinal not in range(128)
94.24.93.131 - - [06/Oct/2016 00:39:11] "POST /signup%2Fusing_phonenumber HTTP/1.1" 500 -
Traceback (most recent call last):
  File "/usr/local/lib/python2.7/dist-packages/flask/app.py", line 2000, in __call__
    return self.wsgi_app(environ, start_response)
  File "/usr/local/lib/python2.7/dist-packages/flask/app.py", line 1991, in wsgi_app
    response = self.make_response(self.handle_exception(e))
  File "/usr/local/lib/python2.7/dist-packages/flask/app.py", line 1567, in handle_exception
    reraise(exc_type, exc_value, tb)
  File "/usr/local/lib/python2.7/dist-packages/flask/app.py", line 1988, in wsgi_app
    response = self.full_dispatch_request()
  File "/usr/local/lib/python2.7/dist-packages/flask/app.py", line 1641, in full_dispatch_request
    rv = self.handle_user_exception(e)
  File "/usr/local/lib/python2.7/dist-packages/flask/app.py", line 1544, in handle_user_exception
    reraise(exc_type, exc_value, tb)
  File "/usr/local/lib/python2.7/dist-packages/flask/app.py", line 1639, in full_dispatch_request
    rv = self.dispatch_request()
  File "/usr/local/lib/python2.7/dist-packages/flask/app.py", line 1625, in dispatch_request
    return self.view_functions[rule.endpoint](**req.view_args)
  File "/root/move_it/app/main/views.py", line 186, in signup_using_phonenumber
    response = methods.send_signup_code(phonenumber=request.json['phonenumber'], code=code)
  File "/root/move_it/app/main/methods.py", line 20, in send_signup_code
    print response.text
UnicodeEncodeError: 'ascii' codec can't encode characters in position 0-4: ordinal not in range(128)
123.59.66.152 - - [06/Oct/2016 04:18:50] "GET http://www.baidu.com/favicon.ico HTTP/1.1" 404 -
31.214.254.248 - - [06/Oct/2016 09:16:44] "POST /signup/using_phonenumber HTTP/1.1" 500 -
Traceback (most recent call last):
  File "/usr/local/lib/python2.7/dist-packages/flask/app.py", line 2000, in __call__
    return self.wsgi_app(environ, start_response)
  File "/usr/local/lib/python2.7/dist-packages/flask/app.py", line 1991, in wsgi_app
    response = self.make_response(self.handle_exception(e))
  File "/usr/local/lib/python2.7/dist-packages/flask/app.py", line 1567, in handle_exception
    reraise(exc_type, exc_value, tb)
  File "/usr/local/lib/python2.7/dist-packages/flask/app.py", line 1988, in wsgi_app
    response = self.full_dispatch_request()
  File "/usr/local/lib/python2.7/dist-packages/flask/app.py", line 1641, in full_dispatch_request
    rv = self.handle_user_exception(e)
  File "/usr/local/lib/python2.7/dist-packages/flask/app.py", line 1544, in handle_user_exception
    reraise(exc_type, exc_value, tb)
  File "/usr/local/lib/python2.7/dist-packages/flask/app.py", line 1639, in full_dispatch_request
    rv = self.dispatch_request()
  File "/usr/local/lib/python2.7/dist-packages/flask/app.py", line 1625, in dispatch_request
    return self.view_functions[rule.endpoint](**req.view_args)
  File "/root/move_it/app/main/views.py", line 186, in signup_using_phonenumber
    response = methods.send_signup_code(phonenumber=request.json['phonenumber'], code=code)
  File "/root/move_it/app/main/methods.py", line 20, in send_signup_code
    print response.text
UnicodeEncodeError: 'ascii' codec can't encode characters in position 0-4: ordinal not in range(128)
